<?xml version="1.0" ?>
<!-- =================================================================================== -->
<!-- |    This document was autogenerated by xacro from manipulator.urdf.xacro         | -->
<!-- |    EDITING THIS FILE BY HAND IS NOT RECOMMENDED                                 | -->
<!-- =================================================================================== -->
<robot name="three_link_manipulator">
  <!-- Materials -->
  <material name="blue">
    <color rgba="0 0 1 1"/>
  </material>
  <material name="green">
    <color rgba="0 1 0 1"/>
  </material>
  <material name="red">
    <color rgba="1 0 0 1"/>
  </material>
  <material name="yellow">
    <color rgba="1 1 0 1"/>
  </material>
  <!-- Base link -->
  <link name="base_link">
    <!-- Visual element -->
    <visual>
      <geometry>
        <cylinder length="0.1" radius="0.1"/>
      </geometry>
      <origin rpy="0 0 0" xyz="0 0 0.05"/>
      <material name="blue"/>
    </visual>
    <!-- Collision element -->
    <collision>
      <geometry>
        <cylinder length="0.1" radius="0.1"/>
      </geometry>
      <origin rpy="0 0 0" xyz="0 0 0.05"/>
    </collision>
  </link>
  <!-- Link 1 -->
  <link name="link1">
    <!-- Visual element -->
    <visual>
      <geometry>
        <cylinder length="1.0" radius="0.05"/>
      </geometry>
      <origin rpy="0 0 0" xyz="0 0 0.5"/>
      <material name="green"/>
    </visual>
    <!-- Collision element -->
    <collision>
      <geometry>
        <cylinder length="1.0" radius="0.05"/>
      </geometry>
      <origin rpy="0 0 0" xyz="0 0 0.5"/>
    </collision>
  </link>
  <joint name="joint1" type="revolute">
    <parent link="base_link"/>
    <child link="link1"/>
    <origin rpy="0 0 0" xyz="0 0 0.1"/>
    <axis xyz="0 0 1"/>
    <limit effort="10.0" lower="-3.14" upper="3.14" velocity="1.0"/>
  </joint>
  <!-- Link 2 -->
  <link name="link2">
    <!-- Visual element -->
    <visual>
      <geometry>
        <cylinder length="1.0" radius="0.05"/>
      </geometry>
      <origin rpy="0 0 0" xyz="0 0 0.5"/>
      <material name="red"/>
    </visual>
    <!-- Collision element -->
    <collision>
      <geometry>
        <cylinder length="1.0" radius="0.05"/>
      </geometry>
      <origin rpy="0 0 0" xyz="0 0 0.5"/>
    </collision>
  </link>
  <joint name="joint2" type="revolute">
    <parent link="link1"/>
    <child link="link2"/>
    <origin rpy="0 0 0" xyz="0 0 1.0"/>
    <axis xyz="0 1 0"/>
    <limit effort="10.0" lower="-3.14" upper="3.14" velocity="1.0"/>
  </joint>
  <!-- Link 3 -->
  <link name="link3">
    <!-- Visual element -->
    <visual>
      <geometry>
        <cylinder length="1.0" radius="0.05"/>
      </geometry>
      <origin rpy="0 0 0" xyz="0 0 0.5"/>
      <material name="yellow"/>
    </visual>
    <!-- Collision element -->
    <collision>
      <geometry>
        <cylinder length="1.0" radius="0.05"/>
      </geometry>
      <origin rpy="0 0 0" xyz="0 0 0.5"/>
    </collision>
  </link>
  <joint name="joint3" type="revolute">
    <parent link="link2"/>
    <child link="link3"/>
    <origin rpy="0 0 0" xyz="0 0 1.0"/>
    <axis xyz="1 0 0"/>
    <limit effort="10.0" lower="-3.14" upper="3.14" velocity="1.0"/>
  </joint>
</robot>
